class exception_handle_using_nestedcatch {
  public static void main(String[] args) {
    System.out.println("..........Start of the code...........");
    System.out.println(" ");

    // try block
    try {
      int x = 10 / 0;
      System.out.println("Value of the X is =" + x);
    }
    // catch block-1
    catch (ArrayIndexOutOfBoundsException e) {
      System.out.println("Array Index Out Of Bounds Exception Occurs");
    }
    // catch block-2
    catch (ArithmeticException e) {
      System.out.println("Arithmetic Exception Occur");
    }
    // catch block-3
    catch (Exception e) {
      System.out.println(e);
    }
    System.out.println(" ");
    System.out.println("..........Rest of the code...........");
  }
}
